Workbook

Sheet General
E4: UNIDAD | K4: LOTE
B5: CARACTERISTICAS | E5: COSTO $ | F5: INCREMENTO COSTO | G5: VENTA $ | H5: VENTA BS | I5: VENTA USDT | K5: COSTO $ | L5: VENTA $ | M5: VENTA BS
B6: POTENCIA Y CONTROL
A7: RIN | B7: N18 DE PALETA TRASERO HORSE CLASE AAA | E7: 49 | G7: =((Fórmulas!C$6/Fórmulas!D$6)/Fórmulas!E$6)*E7 -> 120 | H7: =G7*Fórmulas!B$9 -> 42000 | I7: =E7/0.6 -> 81.666667 | K7: 1 | L7: =((Fórmulas!C$6/Fórmulas!D$6)/0.7)*K7 -> 2.4489796 | M7: =L7*Fórmulas!D$6 -> 857.14286
A8: RIN | B8: N18 DE PALETA TRASERO BERA ORIGINAL | E8: 0 | G8: =((Fórmulas!C$6/Fórmulas!D$6)/Fórmulas!E$6)*E8 -> 0 | H8: =G8*Fórmulas!B$9 -> 0 | I8: =E8/0.6 -> 0 | K8: 1 | L8: =((Fórmulas!C$6/Fórmulas!D$6)/0.7)*K8 -> 2.4489796 | M8: =L8*Fórmulas!D$6 -> 857.14286
A9: RIN | B9: N18 DE PALETA TRASERO HORSE CLASE C | E9: 43.5 | G9: =((Fórmulas!C$6/Fórmulas!D$6)/Fórmulas!E$6)*E9 -> 106.53061 | H9: =G9*Fórmulas!B$9 -> 37285.714 | I9: =E9/0.6 -> 72.5 | K9: 1 | L9: =((Fórmulas!C$6/Fórmulas!D$6)/0.7)*K9 -> 2.4489796 | M9: =L9*Fórmulas!D$6 -> 857.14286
A10: RIN | B10: N18 DE PALETA TRASERO BERA CLASE C | E10: 43.5 | G10: =((Fórmulas!C$6/Fórmulas!D$6)/Fórmulas!E$6)*E10 -> 106.53061 | H10: =G10*Fórmulas!B$9 -> 37285.714 | I10: =E10/0.6 -> 72.5 | K10: 1 | L10: =((Fórmulas!C$6/Fórmulas!D$6)/0.7)*K10 -> 2.4489796 | M10: =L10*Fórmulas!D$6 -> 857.14286
A11: RIN | B11: N18 DE PALETA TRASERO MD CLASE C | E11: 43.5 | G11: =((Fórmulas!C$6/Fórmulas!D$6)/Fórmulas!E$6)*E11 -> 106.53061 | H11: =G11*Fórmulas!B$9 -> 37285.714 | I11: =E11/0.6 -> 72.5 | K11: 1 | L11: =((Fórmulas!C$6/Fórmulas!D$6)/0.7)*K11 -> 2.4489796 | M11: =L11*Fórmulas!D$6 -> 857.14286
A12: RIN | B12: N18 DE PALETA TRASERO NEW HORSE CLASE C | E12: 43.5 | G12: =((Fórmulas!C$6/Fórmulas!D$6)/Fórmulas!E$6)*E12 -> 106.53061 | H12: =G12*Fórmulas!B$9 -> 37285.714 | I12: =E12/0.6 -> 72.5 | K12: 1 | L12: =((Fórmulas!C$6/Fórmulas!D$6)/0.7)*K12 -> 2.4489796 | M12: =L12*Fórmulas!D$6 -> 857.14286
A13: RIN | B13: N18 DE PALETA TRASERO EXPRESS CLASE C | E13: 43.5 | G13: =((Fórmulas!C$6/Fórmulas!D$6)/Fórmulas!E$6)*E13 -> 106.53061 | H13: =G13*Fórmulas!B$9 -> 37285.714 | I13: =E13/0.6 -> 72.5 | K13: 1 | L13: =((Fórmulas!C$6/Fórmulas!D$6)/0.7)*K13 -> 2.4489796 | M13: =L13*Fórmulas!D$6 -> 857.14286
A14: RIN | B14: N18 DE PALETA TRASERO EXPRESS-36 RAYOS | E14: 43.5 | G14: =((Fórmulas!C$6/Fórmulas!D$6)/Fórmulas!E$6)*E14 -> 106.53061 | H14: =G14*Fórmulas!B$9 -> 37285.714 | I14: =E14/0.6 -> 72.5 | K14: 1 | L14: =((Fórmulas!C$6/Fórmulas!D$6)/0.7)*K14 -> 2.4489796 | M14: =L14*Fórmulas!D$6 -> 857.14286
A15: RIN | B15: N18 DE PALETA TRASERO EXPRESS-72 RAYOS PAR FRENO DE BANDA | E15: 111.5 | G15: =((Fórmulas!C$6/Fórmulas!D$6)/Fórmulas!E$6)*E15 -> 273.06122 | H15: =G15*Fórmulas!B$9 -> 95571.429 | I15: =E15/0.6 -> 185.83333 | K15: 1 | L15: =((Fórmulas!C$6/Fórmulas!D$6)/0.7)*K15 -> 2.4489796 | M15: =L15*Fórmulas!D$6 -> 857.14286
A16: RIN | B16: N18 DE PALETA TRASERO EXPRESS-72 RAYOS PAR FRENO DE DISCO | E16: 111.5 | G16: =((Fórmulas!C$6/Fórmulas!D$6)/Fórmulas!E$6)*E16 -> 273.06122 | H16: =G16*Fórmulas!B$9 -> 95571.429 | I16: =E16/0.6 -> 185.83333 | K16: 1 | L16: =((Fórmulas!C$6/Fórmulas!D$6)/0.7)*K16 -> 2.4489796 | M16: =L16*Fórmulas!D$6 -> 857.14286
A17: RIN | B17: N16 DE PALETA TRASERO OWEN CLASE C | E17: 43.5 | G17: =((Fórmulas!C$6/Fórmulas!D$6)/Fórmulas!E$6)*E17 -> 106.53061 | H17: =G17*Fórmulas!B$9 -> 37285.714 | I17: =E17/0.6 -> 72.5 | K17: 1 | L17: =((Fórmulas!C$6/Fórmulas!D$6)/0.7)*K17 -> 2.4489796 | M17: =L17*Fórmulas!D$6 -> 857.14286
A18: RIN | B18: N18 DE PALETA DELANTERO HORSE | E18: 31.5 | G18: =((Fórmulas!C$6/Fórmulas!D$6)/Fórmulas!E$6)*E18 -> 77.142857 | H18: =G18*Fórmulas!B$9 -> 27000 | I18: =E18/0.6 -> 52.5 | K18: 1 | L18: =((Fórmulas!C$6/Fórmulas!D$6)/0.7)*K18 -> 2.4489796 | M18: =L18*Fórmulas!D$6 -> 857.14286
... A24: RIN | B24: PAR DECORATIVO 72 RAYOS TORNEADOS DE EXPRESS CON FRENO DE BANDA | E24: 91.3 | G24: =((Fórmulas!C$6/Fórmulas!D$6)/Fórmulas!E$6)*E24 -> 223.59184 | H24: =G24*Fórmulas!B$9 -> 78257.143 | I24: =E24/0.6 -> 152.16667 | K24: 1 | L24: =((Fórmulas!C$6/Fórmulas!D$6)/0.7)*K24 -> 2.4489796 | M24: =L24*Fórmulas!D$6 -> 857.14286
E25: 0 | G25: =((Fórmulas!C$6/Fórmulas!D$6)/Fórmulas!E$6)*E25 -> 0 | H25: =G25*Fórmulas!B$9 -> 0 | I25: =E25/0.6 -> 0 | K25: 1 | L25: =((Fórmulas!C$6/Fórmulas!D$6)/0.7)*K25 -> 2.4489796 | M25: =L25*Fórmulas!D$6 -> 857.14286
E26: 0 | G26: =((Fórmulas!C$6/Fórmulas!D$6)/Fórmulas!E$6)*E26 -> 0 | H26: =G26*Fórmulas!B$9 -> 0 | I26: =E26/0.6 -> 0 | K26: 1 | L26: =((Fórmulas!C$6/Fórmulas!D$6)/0.7)*K26 -> 2.4489796 | M26: =L26*Fórmulas!D$6 -> 857.14286
E27: 0 | G27: =((Fórmulas!C$6/Fórmulas!D$6)/Fórmulas!E$6)*E27 -> 0 | H27: =G27*Fórmulas!B$9 -> 0 | I27: =E27/0.6 -> 0 | K27: 1 | L27: =((Fórmulas!C$6/Fórmulas!D$6)/0.7)*K27 -> 2.4489796 | M27: =L27*Fórmulas!D$6 -> 857.14286
E28: 0 | G28: =((Fórmulas!C$6/Fórmulas!D$6)/Fórmulas!E$6)*E28 -> 0 | H28: =G28*Fórmulas!B$9 -> 0 | I28: =E28/0.6 -> 0 | K28: 1 | L28: =((Fórmulas!C$6/Fórmulas!D$6)/0.7)*K28 -> 2.4489796 | M28: =L28*Fórmulas!D$6 -> 857.14286
E29: 0 | G29: =((Fórmulas!C$6/Fórmulas!D$6)/Fórmulas!E$6)*E29 -> 0 | H29: =G29*Fórmulas!B$9 -> 0 | I29: =E29/0.6 -> 0 | K29: 1 | L29: =((Fórmulas!C$6/Fórmulas!D$6)/0.7)*K29 -> 2.4489796 | M29: =L29*Fórmulas!D$6 -> 857.14286
E30: 0 | G30: =((Fórmulas!C$6/Fórmulas!D$6)/Fórmulas!E$6)*E30 -> 0 | H30: =G30*Fórmulas!B$9 -> 0 | I30: =E30/0.6 -> 0 | K30: 1 | L30: =((Fórmulas!C$6/Fórmulas!D$6)/0.7)*K30 -> 2.4489796 | M30: =L30*Fórmulas!D$6 -> 857.14286
E31: 0 | G31: =((Fórmulas!C$6/Fórmulas!D$6)/Fórmulas!E$6)*E31 -> 0 | H31: =G31*Fórmulas!B$9 -> 0 | I31: =E31/0.6 -> 0 | K31: 1 | L31: =((Fórmulas!C$6/Fórmulas!D$6)/0.7)*K31 -> 2.4489796 | M31: =L31*Fórmulas!D$6 -> 857.14286
E32: 0 | G32: =((Fórmulas!C$6/Fórmulas!D$6)/Fórmulas!E$6)*E32 -> 0 | H32: =G32*Fórmulas!B$9 -> 0 | I32: =E32/0.6 -> 0 | K32: 1 | L32: =((Fórmulas!C$6/Fórmulas!D$6)/0.7)*K32 -> 2.4489796 | M32: =L32*Fórmulas!D$6 -> 857.14286
A33: RODAJE | B33: CADENA DE ORRIN,PIÑÓN Y CORONA CLASE A DORADO | E33: 14.7 | G33: =((Fórmulas!C$6/Fórmulas!D$6)/Fórmulas!E$6)*E33 -> 36 | H33: =G33*Fórmulas!B$9 -> 12600 | I33: =E33/0.6 -> 24.5 | K33: 1 | L33: =((Fórmulas!C$6/Fórmulas!D$6)/0.7)*K33 -> 2.4489796 | M33: =L33*Fórmulas!D$6 -> 857.14286
A34: RODAJE | B34: CADENA,PIÑÓN Y CORONA CLASE A COLORES(TORNASOL, AZUL, MORADO) | E34: 14 | G34: =((Fórmulas!C$6/Fórmulas!D$6)/Fórmulas!E$6)*E34 -> 34.285714 | H34: =G34*Fórmulas!B$9 -> 12000 | I34: =E34/0.6 -> 23.333333 | K34: 1 | L34: =((Fórmulas!C$6/Fórmulas!D$6)/0.7)*K34 -> 2.4489796 | M34: =L34*Fórmulas!D$6 -> 857.14286
A35: RODAJE | B35: CADENA,PIÑÓN Y CORONA CLASE A DORADO | E35: 10 | G35: =((Fórmulas!C$6/Fórmulas!D$6)/Fórmulas!E$6)*E35 -> 24.489796 | H35: =G35*Fórmulas!B$9 -> 8571.4286 | I35: =E35/0.6 -> 16.666667 | K35: 1 | L35: =((Fórmulas!C$6/Fórmulas!D$6)/0.7)*K35 -> 2.4489796 | M35: =L35*Fórmulas!D$6 -> 857.14286
A36: RODAJE | B36: CADENA,PIÑÓN Y CORONA REFORZADO NEGRO | E36: 8 | G36: =((Fórmulas!C$6/Fórmulas!D$6)/Fórmulas!E$6)*E36 -> 19.591837 | H36: =G36*Fórmulas!B$9 -> 6857.1429 | I36: =E36/0.6 -> 13.333333 | K36: 1 | L36: =((Fórmulas!C$6/Fórmulas!D$6)/0.7)*K36 -> 2.4489796 | M36: =L36*Fórmulas!D$6 -> 857.14286
A37: RODAJE | B37: CADENA,PIÑÓN Y CORONA REFORZADO CROMADO CLASE C | E37: 7 | G37: =((Fórmulas!C$6/Fórmulas!D$6)/Fórmulas!E$6)*E37 -> 17.142857 | H37: =G37*Fórmulas!B$9 -> 6000 | I37: =E37/0.6 -> 11.666667 | K37: 1 | L37: =((Fórmulas!C$6/Fórmulas!D$6)/0.7)*K37 -> 2.4489796 | M37: =L37*Fórmulas!D$6 -> 857.14286
A38: RODAJE | B38: CADENA, PIÑÓN Y CORONA ALDRICH CLASE A | E38: 13 | G38: =((Fórmulas!C$6/Fórmulas!D$6)/Fórmulas!E$6)*E38 -> 31.836735 | H38: =G38*Fórmulas!B$9 -> 11142.857 | I38: =E38/0.6 -> 21.666667 | K38: 1 | L38: =((Fórmulas!C$6/Fórmulas!D$6)/0.7)*K38 -> 2.4489796 | M38: =L38*Fórmulas!D$6 -> 857.14286
A39: RODAJE | B39: CADENA, PIÑÓN Y CORONA MD LECHUZA ORIGINAL 2025 | E39: 17 | G39: =((Fórmulas!C$6/Fórmulas!D$6)/Fórmulas!E$6)*E39 -> 41.632653 | H39: =G39*Fórmulas!B$9 -> 14571.429 | I39: =E39/0.6 -> 28.333333 | K39: 1 | L39: =((Fórmulas!C$6/Fórmulas!D$6)/0.7)*K39 -> 2.4489796 | M39: =L39*Fórmulas!D$6 -> 857.14286
A40: RODAJE | B40: CADENA,PIÑÓN Y CORONA 520 COMPATIBLE MD LECHUZA, TX, DT BERA | E40: 25 | G40: =((Fórmulas!C$6/Fórmulas!D$6)/Fórmulas!E$6)*E40 -> 61.22449 | H40: =G40*Fórmulas!B$9 -> 21428.571 | I40: =E40/0.6 -> 41.666667 | K40: 1 | L40: =((Fórmulas!C$6/Fórmulas!D$6)/0.7)*K40 -> 2.4489796 | M40: =L40*Fórmulas!D$6 -> 857.14286
A41: CADENA | B41: 525 ORRIN DORADA | E41: 22 | G41: =((Fórmulas!C$6/Fórmulas!D$6)/Fórmulas!E$6)*E41 -> 53.877551 | H41: =G41*Fórmulas!B$9 -> 18857.143 | I41: =E41/0.6 -> 36.666667 | K41: 1 | L41: =((Fórmulas!C$6/Fórmulas!D$6)/0.7)*K41 -> 2.4489796 | M41: =L41*Fórmulas!D$6 -> 857.14286
A42: CADENA | B42: 525 DORADA REFORZADA | E42: 13 | G42: =((Fórmulas!C$6/Fórmulas!D$6)/Fórmulas!E$6)*E42 -> 31.836735 | H42: =G42*Fórmulas!B$9 -> 11142.857 | I42: =E42/0.6 -> 21.666667 | K42: 1 | L42: =((Fórmulas!C$6/Fórmulas!D$6)/0.7)*K42 -> 2.4489796 | M42: =L42*Fórmulas!D$6 -> 857.14286
A43: CADENA | B43: 428 ECONÓMICA REFORZADA | E43: 4.8 | G43: =((Fórmulas!C$6/Fórmulas!D$6)/Fórmulas!E$6)*E43 -> 11.755102 | H43: =G43*Fórmulas!B$9 -> 4114.2857 | I43: =E43/0.6 -> 8 | K43: 1 | L43: =((Fórmulas!C$6/Fórmulas!D$6)/0.7)*K43 -> 2.4489796 | M43: =L43*Fórmulas!D$6 -> 857.14286
A44: CADENA | B44: 428 NEGRA REFORZADA | E44: 6 | G44: =((Fórmulas!C$6/Fórmulas!D$6)/Fórmulas!E$6)*E44 -> 14.693878 | H44: =G44*Fórmulas!B$9 -> 5142.8571 | I44: =E44/0.6 -> 10 | K44: 1 | L44: =((Fórmulas!C$6/Fórmulas!D$6)/0.7)*K44 -> 2.4489796 | M44: =L44*Fórmulas!D$6 -> 857.14286
... A46: CADENA | B46: 428 ORRIN SÚPERREFORZADA | E46: 12 | G46: =((Fórmulas!C$6/Fórmulas!D$6)/Fórmulas!E$6)*E46 -> 29.387755 | H46: =G46*Fórmulas!B$9 -> 10285.714 | I46: =E46/0.6 -> 20 | K46: 1 | L46: =((Fórmulas!C$6/Fórmulas!D$6)/0.7)*K46 -> 2.4489796 | M46: =L46*Fórmulas!D$6 -> 857.14286
E47: 0 | G47: =((Fórmulas!C$6/Fórmulas!D$6)/Fórmulas!E$6)*E47 -> 0 | H47: =G47*Fórmulas!B$9 -> 0 | I47: =E47/0.6 -> 0 | K47: 1 | L47: =((Fórmulas!C$6/Fórmulas!D$6)/0.7)*K47 -> 2.4489796 | M47: =L47*Fórmulas!D$6 -> 857.14286
E48: 0 | G48: =((Fórmulas!C$6/Fórmulas!D$6)/Fórmulas!E$6)*E48 -> 0 | H48: =G48*Fórmulas!B$9 -> 0 | I48: =E48/0.6 -> 0 | K48: 1 | L48: =((Fórmulas!C$6/Fórmulas!D$6)/0.7)*K48 -> 2.4489796 | M48: =L48*Fórmulas!D$6 -> 857.14286
E49: 0 | G49: =((Fórmulas!C$6/Fórmulas!D$6)/Fórmulas!E$6)*E49 -> 0 | H49: =G49*Fórmulas!B$9 -> 0 | I49: =E49/0.6 -> 0 | K49: 1 | L49: =((Fórmulas!C$6/Fórmulas!D$6)/0.7)*K49 -> 2.4489796 | M49: =L49*Fórmulas!D$6 -> 857.14286
...

Sheet Secundario
A6: CADENA | B6: CARACTERISTICAS | E6: COSTO $ | F6: INCREMENTO COSTO | G6: VENTA $ | H6: VENTA BS | I6: VENTA USDT | K6: COSTO $ | L6: VENTA $ | M6: VENTA BS
A8: ACEITE | B8: GRANEL 1 LT ECONOMICO | E8: 3 | G8: =((Fórmulas!C$6/Fórmulas!D$6)/Fórmulas!E$8)*E8 -> 6.4285714 | H8: =G8*Fórmulas!B$9 -> 2250 | I8: =E8/0.6 -> 5 | K8: 1 | L8: =((Fórmulas!C$6/Fórmulas!D$6)/0.8)*K8 -> 2.1428571 | M8: =L8*Fórmulas!D$6 -> 750
A9: ACEITE | B9: GRANEL 1 LT CHINO CLASE A | E9: 3.5 | G9: =((Fórmulas!C$6/Fórmulas!D$6)/Fórmulas!E$8)*E9 -> 7.5 | H9: =G9*Fórmulas!B$9 -> 2625 | I9: =E9/0.6 -> 5.8333333 | K9: 1 | L9: =((Fórmulas!C$6/Fórmulas!D$6)/0.8)*K9 -> 2.1428571 | M9: =L9*Fórmulas!D$6 -> 750
A10: CAMARA | B10: HORSE CON VALVULAS Y RESORTE CLASE C | E10: 26 | G10: =((Fórmulas!C$6/Fórmulas!D$6)/Fórmulas!E$8)*E10 -> 55.714286 | H10: =G10*Fórmulas!B$9 -> 19500 | I10: =E10/0.6 -> 43.333333 | K10: 1 | L10: =((Fórmulas!C$6/Fórmulas!D$6)/0.8)*K10 -> 2.1428571 | M10: =L10*Fórmulas!D$6 -> 750
A11: CAMARA | B11: CG 200 SOLA SIN RESORTE Y SIN VALVULAS | E11: 23 | G11: =((Fórmulas!C$6/Fórmulas!D$6)/Fórmulas!E$8)*E11 -> 49.285714 | H11: =G11*Fórmulas!B$9 -> 17250 | I11: =E11/0.6 -> 38.333333 | K11: 1 | L11: =((Fórmulas!C$6/Fórmulas!D$6)/0.8)*K11 -> 2.1428571 | M11: =L11*Fórmulas!D$6 -> 750
A12: CAMARA | B12: DT BERA 200 SOLA SIN ARBOL DE LEVA NI MARTILLERA | E12: 73 | G12: =((Fórmulas!C$6/Fórmulas!D$6)/Fórmulas!E$8)*E12 -> 156.42857 | H12: =G12*Fórmulas!B$9 -> 54750 | I12: =E12/0.6 -> 121.66667 | K12: 1 | L12: =((Fórmulas!C$6/Fórmulas!D$6)/0.8)*K12 -> 2.1428571 | M12: =L12*Fórmulas!D$6 -> 750
A13: CAMARA | B13: TX CON MARTILLERA Y TAPA VALVULAS | E13: 41 | G13: =((Fórmulas!C$6/Fórmulas!D$6)/Fórmulas!E$8)*E13 -> 87.857143 | H13: =G13*Fórmulas!B$9 -> 30750 | I13: =E13/0.6 -> 68.333333 | K13: 1 | L13: =((Fórmulas!C$6/Fórmulas!D$6)/0.8)*K13 -> 2.1428571 | M13: =L13*Fórmulas!D$6 -> 750
A14: CAMARA | B14: HJ COOL COMPLETA (MARTILLOS Y ARBOL DE LEVA) | E14: 73 | G14: =((Fórmulas!C$6/Fórmulas!D$6)/Fórmulas!E$8)*E14 -> 156.42857 | H14: =G14*Fórmulas!B$9 -> 54750 | I14: =E14/0.6 -> 121.66667 | K14: 1 | L14: =((Fórmulas!C$6/Fórmulas!D$6)/0.8)*K14 -> 2.1428571 | M14: =L14*Fórmulas!D$6 -> 750
A15: CAMARA | B15: GN COMPLETA (MARTILLO Y ARBOL DE LEVA) | E15: 73 | G15: =((Fórmulas!C$6/Fórmulas!D$6)/Fórmulas!E$8)*E15 -> 156.42857 | H15: =G15*Fórmulas!B$9 -> 54750 | I15: =E15/0.6 -> 121.66667 | K15: 1 | L15: =((Fórmulas!C$6/Fórmulas!D$6)/0.8)*K15 -> 2.1428571 | M15: =L15*Fórmulas!D$6 -> 750
A16: CAMARA | B16: HORSE Y CG SENCILLA SOLA | E16: 27 | G16: =((Fórmulas!C$6/Fórmulas!D$6)/Fórmulas!E$8)*E16 -> 57.857143 | H16: =G16*Fórmulas!B$9 -> 20250 | I16: =E16/0.6 -> 45 | K16: 1 | L16: =((Fórmulas!C$6/Fórmulas!D$6)/0.8)*K16 -> 2.1428571 | M16: =L16*Fórmulas!D$6 -> 750
A17: CAMARA | B17: AUTOMATICA GY6 SOLA | E17: 19 | G17: =((Fórmulas!C$6/Fórmulas!D$6)/Fórmulas!E$8)*E17 -> 40.714286 | H17: =G17*Fórmulas!B$9 -> 14250 | I17: =E17/0.6 -> 31.666667 | K17: 1 | L17: =((Fórmulas!C$6/Fórmulas!D$6)/0.8)*K17 -> 2.1428571 | M17: =L17*Fórmulas!D$6 -> 750
E18: 0 | G18: =((Fórmulas!C$6/Fórmulas!D$6)/Fórmulas!E$8)*E18 -> 0 | H18: =G18*Fórmulas!B$9 -> 0 | I18: =E18/0.6 -> 0 | K18: 1 | L18: =((Fórmulas!C$6/Fórmulas!D$6)/0.8)*K18 -> 2.1428571 | M18: =L18*Fórmulas!D$6 -> 750
E19: 0 | G19: =((Fórmulas!C$6/Fórmulas!D$6)/Fórmulas!E$8)*E19 -> 0 | H19: =G19*Fórmulas!B$9 -> 0 | I19: =E19/0.6 -> 0 | K19: 1 | L19: =((Fórmulas!C$6/Fórmulas!D$6)/0.8)*K19 -> 2.1428571 | M19: =L19*Fórmulas!D$6 -> 750
E20: 0 | G20: =((Fórmulas!C$6/Fórmulas!D$6)/Fórmulas!E$8)*E20 -> 0 | H20: =G20*Fórmulas!B$9 -> 0 | I20: =E20/0.6 -> 0 | K20: 1 | L20: =((Fórmulas!C$6/Fórmulas!D$6)/0.8)*K20 -> 2.1428571 | M20: =L20*Fórmulas!D$6 -> 750
E21: 0 | G21: =((Fórmulas!C$6/Fórmulas!D$6)/Fórmulas!E$8)*E21 -> 0 | H21: =G21*Fórmulas!B$9 -> 0 | I21: =E21/0.6 -> 0 | K21: 1 | L21: =((Fórmulas!C$6/Fórmulas!D$6)/0.8)*K21 -> 2.1428571 | M21: =L21*Fórmulas!D$6 -> 750
E22: 0 | G22: =((Fórmulas!C$6/Fórmulas!D$6)/Fórmulas!E$8)*E22 -> 0 | H22: =G22*Fórmulas!B$9 -> 0 | I22: =E22/0.6 -> 0 | K22: 1 | L22: =((Fórmulas!C$6/Fórmulas!D$6)/0.8)*K22 -> 2.1428571 | M22: =L22*Fórmulas!D$6 -> 750
E23: 0 | G23: =((Fórmulas!C$6/Fórmulas!D$6)/Fórmulas!E$8)*E23 -> 0 | H23: =G23*Fórmulas!B$9 -> 0 | I23: =E23/0.6 -> 0 | K23: 1 | L23: =((Fórmulas!C$6/Fórmulas!D$6)/0.8)*K23 -> 2.1428571 | M23: =L23*Fórmulas!D$6 -> 750
E24: 0 | G24: =((Fórmulas!C$6/Fórmulas!D$6)/Fórmulas!E$8)*E24 -> 0 | H24: =G24*Fórmulas!B$9 -> 0 | I24: =E24/0.6 -> 0 | K24: 1 | L24: =((Fórmulas!C$6/Fórmulas!D$6)/0.8)*K24 -> 2.1428571 | M24: =L24*Fórmulas!D$6 -> 750
E25: 0 | G25: =((Fórmulas!C$6/Fórmulas!D$6)/Fórmulas!E$8)*E25 -> 0 | H25: =G25*Fórmulas!B$9 -> 0 | I25: =E25/0.6 -> 0 | K25: 1 | L25: =((Fórmulas!C$6/Fórmulas!D$6)/0.8)*K25 -> 2.1428571 | M25: =L25*Fórmulas!D$6 -> 750
E26: 0 | G26: =((Fórmulas!C$6/Fórmulas!D$6)/Fórmulas!E$8)*E26 -> 0 | H26: =G26*Fórmulas!B$9 -> 0 | I26: =E26/0.6 -> 0 | K26: 1 | L26: =((Fórmulas!C$6/Fórmulas!D$6)/0.8)*K26 -> 2.1428571 | M26: =L26*Fórmulas!D$6 -> 750
E27: 0 | G27: =((Fórmulas!C$6/Fórmulas!D$6)/Fórmulas!E$8)*E27 -> 0 | H27: =G27*Fórmulas!B$9 -> 0 | I27: =E27/0.6 -> 0 | K27: 1 | L27: =((Fórmulas!C$6/Fórmulas!D$6)/0.8)*K27 -> 2.1428571 | M27: =L27*Fórmulas!D$6 -> 750
E28: 0 | G28: =((Fórmulas!C$6/Fórmulas!D$6)/Fórmulas!E$8)*E28 -> 0 | H28: =G28*Fórmulas!B$9 -> 0 | I28: =E28/0.6 -> 0 | K28: 1 | L28: =((Fórmulas!C$6/Fórmulas!D$6)/0.8)*K28 -> 2.1428571 | M28: =L28*Fórmulas!D$6 -> 750
E29: 0 | G29: =((Fórmulas!C$6/Fórmulas!D$6)/Fórmulas!E$8)*E29 -> 0 | H29: =G29*Fórmulas!B$9 -> 0 | I29: =E29/0.6 -> 0 | K29: 1 | L29: =((Fórmulas!C$6/Fórmulas!D$6)/0.8)*K29 -> 2.1428571 | M29: =L29*Fórmulas!D$6 -> 750
... E48: 0 | G48: =((Fórmulas!C$6/Fórmulas!D$6)/Fórmulas!E$8)*E48 -> 0 | H48: =G48*Fórmulas!B$9 -> 0 | I48: =E48/0.6 -> 0 | K48: 1 | L48: =((Fórmulas!C$6/Fórmulas!D$6)/0.8)*K48 -> 2.1428571 | M48: =L48*Fórmulas!D$6 -> 750
I49: =E49/0.6 -> 0

Sheet Productos de Bajo Costo
E4: UNIDAD | K4: LOTE
B5: CARACTERISTICAS | E5: COSTO $ | F5: INCREMENTO COSTO | G5: VENTA $ | H5: VENTA BS | I5: VENTA USDT | J5: VENTA BS(USDT) | K5: COSTO $ | L5: VENTA $ | M5: VENTA BS
B6: POTENCIA Y CONTROL
A7: CORONA | B7: 35 RIN PALETA CROMADA | E7: 3 | G7: =((Fórmulas!C$7/Fórmulas!D$7)/Fórmulas!E$7)*E7 -> 8.5714286 | H7: =G7*Fórmulas!B$9 -> 3000 | I7: =E7/Fórmulas!E$7 -> 5 | J7: =G7*Fórmulas!B$10 -> 5142.8571 | K7: 1 | L7: =((Fórmulas!C$6/Fórmulas!D$6)/0.7)*K7 -> 2.4489796 | M7: =L7*Fórmulas!D$6 -> 857.14286
A8: CORONA | B8: 36 RIN PALETA CROMADA | E8: 3 | G8: =((Fórmulas!C$7/Fórmulas!D$7)/Fórmulas!E$7)*E8 -> 8.5714286 | H8: =G8*Fórmulas!B$9 -> 3000 | I8: =E8/Fórmulas!E$7 -> 5 | J8: =G8*Fórmulas!B$10 -> 5142.8571 | K8: 1 | L8: =((Fórmulas!C$6/Fórmulas!D$6)/0.7)*K8 -> 2.4489796 | M8: =L8*Fórmulas!D$6 -> 857.14286
A9: CORONA | B9: 37 RIN PALETA CROMADA | E9: 3 | G9: =((Fórmulas!C$7/Fórmulas!D$7)/Fórmulas!E$7)*E9 -> 8.5714286 | H9: =G9*Fórmulas!B$9 -> 3000 | I9: =E9/Fórmulas!E$7 -> 5 | J9: =G9*Fórmulas!B$10 -> 5142.8571 | K9: 1 | L9: =((Fórmulas!C$6/Fórmulas!D$6)/0.7)*K9 -> 2.4489796 | M9: =L9*Fórmulas!D$6 -> 857.14286
A10: CORONA | B10: 38 RIN PALETA CROMADA | E10: 3 | G10: =((Fórmulas!C$7/Fórmulas!D$7)/Fórmulas!E$7)*E10 -> 8.5714286 | H10: =G10*Fórmulas!B$9 -> 3000 | I10: =E10/Fórmulas!E$7 -> 5 | J10: =G10*Fórmulas!B$10 -> 5142.8571 | K10: 1 | L10: =((Fórmulas!C$6/Fórmulas!D$6)/0.7)*K10 -> 2.4489796 | M10: =L10*Fórmulas!D$6 -> 857.14286
A11: CORONA | B11: 39 RIN PALETA CROMADA | E11: 3 | G11: =((Fórmulas!C$7/Fórmulas!D$7)/Fórmulas!E$7)*E11 -> 8.5714286 | H11: =G11*Fórmulas!B$9 -> 3000 | I11: =E11/Fórmulas!E$7 -> 5 | J11: =G11*Fórmulas!B$10 -> 5142.8571 | K11: 1 | L11: =((Fórmulas!C$6/Fórmulas!D$6)/0.7)*K11 -> 2.4489796 | M11: =L11*Fórmulas!D$6 -> 857.14286
A12: CORONA | B12: 40 RIN PALETA CROMADA | E12: 3 | G12: =((Fórmulas!C$7/Fórmulas!D$7)/Fórmulas!E$7)*E12 -> 8.5714286 | H12: =G12*Fórmulas!B$9 -> 3000 | I12: =E12/Fórmulas!E$7 -> 5 | J12: =G12*Fórmulas!B$10 -> 5142.8571 | K12: 1 | L12: =((Fórmulas!C$6/Fórmulas!D$6)/0.7)*K12 -> 2.4489796 | M12: =L12*Fórmulas!D$6 -> 857.14286
A13: CORONA | B13: 41 RIN PALETA CROMADA | E13: 3.3 | G13: =((Fórmulas!C$7/Fórmulas!D$7)/Fórmulas!E$7)*E13 -> 9.4285714 | H13: =G13*Fórmulas!B$9 -> 3300 | I13: =E13/Fórmulas!E$7 -> 5.5 | J13: =G13*Fórmulas!B$10 -> 5657.1429 | K13: 1 | L13: =((Fórmulas!C$6/Fórmulas!D$6)/0.7)*K13 -> 2.4489796 | M13: =L13*Fórmulas!D$6 -> 857.14286
A14: CORONA | B14: 42 RIN PALETA CROMADA | E14: 3.3 | G14: =((Fórmulas!C$7/Fórmulas!D$7)/Fórmulas!E$7)*E14 -> 9.4285714 | H14: =G14*Fórmulas!B$9 -> 3300 | I14: =E14/Fórmulas!E$7 -> 5.5 | J14: =G14*Fórmulas!B$10 -> 5657.1429 | K14: 1 | L14: =((Fórmulas!C$6/Fórmulas!D$6)/0.7)*K14 -> 2.4489796 | M14: =L14*Fórmulas!D$6 -> 857.14286
A15: CORONA | B15: 43 RIN PALETA CROMADA | E15: 3.3 | G15: =((Fórmulas!C$7/Fórmulas!D$7)/Fórmulas!E$7)*E15 -> 9.4285714 | H15: =G15*Fórmulas!B$9 -> 3300 | I15: =E15/Fórmulas!E$7 -> 5.5 | J15: =G15*Fórmulas!B$10 -> 5657.1429 | K15: 1 | L15: =((Fórmulas!C$6/Fórmulas!D$6)/0.7)*K15 -> 2.4489796 | M15: =L15*Fórmulas!D$6 -> 857.14286
A16: CORONA | B16: 44 RIN PALETA CROMADA | E16: 3.3 | G16: =((Fórmulas!C$7/Fórmulas!D$7)/Fórmulas!E$7)*E16 -> 9.4285714 | H16: =G16*Fórmulas!B$9 -> 3300 | I16: =E16/Fórmulas!E$7 -> 5.5 | J16: =G16*Fórmulas!B$10 -> 5657.1429 | K16: 1 | L16: =((Fórmulas!C$6/Fórmulas!D$6)/0.7)*K16 -> 2.4489796 | M16: =L16*Fórmulas!D$6 -> 857.14286
A17: CORONA | B17: 45 RIN PALETA CROMADA | E17: 3.3 | G17: =((Fórmulas!C$7/Fórmulas!D$7)/Fórmulas!E$7)*E17 -> 9.4285714 | H17: =G17*Fórmulas!B$9 -> 3300 | I17: =E17/Fórmulas!E$7 -> 5.5 | J17: =G17*Fórmulas!B$10 -> 5657.1429 | K17: 1 | L17: =((Fórmulas!C$6/Fórmulas!D$6)/0.7)*K17 -> 2.4489796 | M17: =L17*Fórmulas!D$6 -> 857.14286
A18: CORONA | B18: 35 RIN RAYOS CROMADA | E18: 3 | G18: =((Fórmulas!C$7/Fórmulas!D$7)/Fórmulas!E$7)*E18 -> 8.5714286 | H18: =G18*Fórmulas!B$9 -> 3000 | I18: =E18/Fórmulas!E$7 -> 5 | J18: =G18*Fórmulas!B$10 -> 5142.8571 | K18: 1 | L18: =((Fórmulas!C$6/Fórmulas!D$6)/0.7)*K18 -> 2.4489796 | M18: =L18*Fórmulas!D$6 -> 857.14286
... A105: CORONA | B105: 45 MD DORADA | E105: 4 | G105: =((Fórmulas!C$7/Fórmulas!D$7)/Fórmulas!E$7)*E105 -> 11.428571 | H105: =G105*Fórmulas!B$9 -> 4000 | I105: =E105/Fórmulas!E$7 -> 6.6666667 | J105: =G105*Fórmulas!B$10 -> 6857.1429 | K105: 1 | L105: =((Fórmulas!C$6/Fórmulas!D$6)/0.7)*K105 -> 2.4489796 | M105: =L105*Fórmulas!D$6 -> 857.14286
E106: 0 | G106: =((Fórmulas!C$7/Fórmulas!D$7)/Fórmulas!E$7)*E106 -> 0 | H106: =G106*Fórmulas!B$9 -> 0 | I106: =E106/Fórmulas!E$7 -> 0 | J106: =G106*Fórmulas!B$10 -> 0 | K106: 1 | L106: =((Fórmulas!C$6/Fórmulas!D$6)/0.7)*K106 -> 2.4489796 | M106: =L106*Fórmulas!D$6 -> 857.14286
A107: CORONA | B107: 42 TX CROMADA | E107: 3.3 | G107: =((Fórmulas!C$7/Fórmulas!D$7)/Fórmulas!E$7)*E107 -> 9.4285714 | H107: =G107*Fórmulas!B$9 -> 3300 | I107: =E107/Fórmulas!E$7 -> 5.5 | J107: =G107*Fórmulas!B$10 -> 5657.1429 | K107: 1 | L107: =((Fórmulas!C$6/Fórmulas!D$6)/0.7)*K107 -> 2.4489796 | M107: =L107*Fórmulas!D$6 -> 857.14286
A108: CORONA | B108: 43 TX CROMADA | E108: 3.3 | G108: =((Fórmulas!C$7/Fórmulas!D$7)/Fórmulas!E$7)*E108 -> 9.4285714 | H108: =G108*Fórmulas!B$9 -> 3300 | I108: =E108/Fórmulas!E$7 -> 5.5 | J108: =G108*Fórmulas!B$10 -> 5657.1429 | K108: 1 | L108: =((Fórmulas!C$6/Fórmulas!D$6)/0.7)*K108 -> 2.4489796 | M108: =L108*Fórmulas!D$6 -> 857.14286
A109: CORONA | B109: 44 TX CROMADA | E109: 3.3 | G109: =((Fórmulas!C$7/Fórmulas!D$7)/Fórmulas!E$7)*E109 -> 9.4285714 | H109: =G109*Fórmulas!B$9 -> 3300 | I109: =E109/Fórmulas!E$7 -> 5.5 | J109: =G109*Fórmulas!B$10 -> 5657.1429 | K109: 1 | L109: =((Fórmulas!C$6/Fórmulas!D$6)/0.7)*K109 -> 2.4489796 | M109: =L109*Fórmulas!D$6 -> 857.14286
A110: CORONA | B110: 45 TX CROMADA | E110: 3.3 | G110: =((Fórmulas!C$7/Fórmulas!D$7)/Fórmulas!E$7)*E110 -> 9.4285714 | H110: =G110*Fórmulas!B$9 -> 3300 | I110: =E110/Fórmulas!E$7 -> 5.5 | J110: =G110*Fórmulas!B$10 -> 5657.1429 | K110: 1 | L110: =((Fórmulas!C$6/Fórmulas!D$6)/0.7)*K110 -> 2.4489796 | M110: =L110*Fórmulas!D$6 -> 857.14286
A111: CORONA | B111: 42 TX NEGRA | E111: 4.3 | G111: =((Fórmulas!C$7/Fórmulas!D$7)/Fórmulas!E$7)*E111 -> 12.285714 | H111: =G111*Fórmulas!B$9 -> 4300 | I111: =E111/Fórmulas!E$7 -> 7.1666667 | J111: =G111*Fórmulas!B$10 -> 7371.4286 | K111: 1 | L111: =((Fórmulas!C$6/Fórmulas!D$6)/0.7)*K111 -> 2.4489796 | M111: =L111*Fórmulas!D$6 -> 857.14286
A112: CORONA | B112: 43 TX NEGRA | E112: 4.3 | G112: =((Fórmulas!C$7/Fórmulas!D$7)/Fórmulas!E$7)*E112 -> 12.285714 | H112: =G112*Fórmulas!B$9 -> 4300 | I112: =E112/Fórmulas!E$7 -> 7.1666667 | J112: =G112*Fórmulas!B$10 -> 7371.4286 | K112: 1 | L112: =((Fórmulas!C$6/Fórmulas!D$6)/0.7)*K112 -> 2.4489796 | M112: =L112*Fórmulas!D$6 -> 857.14286
A113: CORONA | B113: 44 TX NEGRA | E113: 4.3 | G113: =((Fórmulas!C$7/Fórmulas!D$7)/Fórmulas!E$7)*E113 -> 12.285714 | H113: =G113*Fórmulas!B$9 -> 4300 | I113: =E113/Fórmulas!E$7 -> 7.1666667 | J113: =G113*Fórmulas!B$10 -> 7371.4286 | K113: 1 | L113: =((Fórmulas!C$6/Fórmulas!D$6)/0.7)*K113 -> 2.4489796 | M113: =L113*Fórmulas!D$6 -> 857.14286
A114: CORONA | B114: 45 TX NEGRA | E114: 4.3 | G114: =((Fórmulas!C$7/Fórmulas!D$7)/Fórmulas!E$7)*E114 -> 12.285714 | H114: =G114*Fórmulas!B$9 -> 4300 | I114: =E114/Fórmulas!E$7 -> 7.1666667 | J114: =G114*Fórmulas!B$10 -> 7371.4286 | K114: 1 | L114: =((Fórmulas!C$6/Fórmulas!D$6)/0.7)*K114 -> 2.4489796 | M114: =L114*Fórmulas!D$6 -> 857.14286
A115: CORONA | B115: 42 TX DORADA | E115: 3.7 | G115: =((Fórmulas!C$7/Fórmulas!D$7)/Fórmulas!E$7)*E115 -> 10.571429 | H115: =G115*Fórmulas!B$9 -> 3700 | I115: =E115/Fórmulas!E$7 -> 6.1666667 | J115: =G115*Fórmulas!B$10 -> 6342.8571 | K115: 1 | L115: =((Fórmulas!C$6/Fórmulas!D$6)/0.7)*K115 -> 2.4489796 | M115: =L115*Fórmulas!D$6 -> 857.14286
A116: CORONA | B116: 43 TX DORADA | E116: 3.7 | G116: =((Fórmulas!C$7/Fórmulas!D$7)/Fórmulas!E$7)*E116 -> 10.571429 | H116: =G116*Fórmulas!B$9 -> 3700 | I116: =E116/Fórmulas!E$7 -> 6.1666667 | J116: =G116*Fórmulas!B$10 -> 6342.8571 | K116: 1 | L116: =((Fórmulas!C$6/Fórmulas!D$6)/0.7)*K116 -> 2.4489796 | M116: =L116*Fórmulas!D$6 -> 857.14286
A117: CORONA | B117: 44 TX DORADA | E117: 3.7 | G117: =((Fórmulas!C$7/Fórmulas!D$7)/Fórmulas!E$7)*E117 -> 10.571429 | H117: =G117*Fórmulas!B$9 -> 3700 | I117: =E117/Fórmulas!E$7 -> 6.1666667 | J117: =G117*Fórmulas!B$10 -> 6342.8571 | K117: 1 | L117: =((Fórmulas!C$6/Fórmulas!D$6)/0.7)*K117 -> 2.4489796 | M117: =L117*Fórmulas!D$6 -> 857.14286
A118: CORONA | B118: 45 TX DORADA | E118: 3.7 | G118: =((Fórmulas!C$7/Fórmulas!D$7)/Fórmulas!E$7)*E118 -> 10.571429 | H118: =G118*Fórmulas!B$9 -> 3700 | I118: =E118/Fórmulas!E$7 -> 6.1666667 | J118: =G118*Fórmulas!B$10 -> 6342.8571 | K118: 1 | L118: =((Fórmulas!C$6/Fórmulas!D$6)/0.7)*K118 -> 2.4489796 | M118: =L118*Fórmulas!D$6 -> 857.14286
E119: 0 | G119: =((Fórmulas!C$7/Fórmulas!D$7)/Fórmulas!E$7)*E119 -> 0 | H119: =G119*Fórmulas!B$9 -> 0 | I119: =E119/Fórmulas!E$7 -> 0 | J119: =G119*Fórmulas!B$10 -> 0 | K119: 1 | L119: =((Fórmulas!C$6/Fórmulas!D$6)/0.7)*K119 -> 2.4489796 | M119: =L119*Fórmulas!D$6 -> 857.14286
A120: PIÑÓN | B120: 14 CG CROMADO (SIN BORDE) | E120: 0.9 | G120: =((Fórmulas!C$7/Fórmulas!D$7)/Fórmulas!E$7)*E120 -> 2.5714286 | H120: =G120*Fórmulas!B$9 -> 900 | I120: =E120/Fórmulas!E$7 -> 1.5 | J120: =G120*Fórmulas!B$10 -> 1542.8571 | K120: 1 | L120: =((Fórmulas!C$6/Fórmulas!D$6)/0.7)*K120 -> 2.4489796 | M120: =L120*Fórmulas!D$6 -> 857.14286
A121: PIÑÓN | B121: 15 CG CROMADO (SIN BORDE) | E121: 0.9 | G121: =((Fórmulas!C$7/Fórmulas!D$7)/Fórmulas!E$7)*E121 -> 2.5714286 | H121: =G121*Fórmulas!B$9 -> 900 | I121: =E121/Fórmulas!E$7 -> 1.5 | J121: =G121*Fórmulas!B$10 -> 1542.8571 | K121: 1 | L121: =((Fórmulas!C$6/Fórmulas!D$6)/0.7)*K121 -> 2.4489796 | M121: =L121*Fórmulas!D$6 -> 857.14286
A122: PIÑÓN | B122: 16 CG CROMADO (SIN BORDE) | E122: 0.9 | G122: =((Fórmulas!C$7/Fórmulas!D$7)/Fórmulas!E$7)*E122 -> 2.5714286 | H122: =G122*Fórmulas!B$9 -> 900 | I122: =E122/Fórmulas!E$7 -> 1.5 | J122: =G122*Fórmulas!B$10 -> 1542.8571 | K122: 1 | L122: =((Fórmulas!C$6/Fórmulas!D$6)/0.7)*K122 -> 2.4489796 | M122: =L122*Fórmulas!D$6 -> 857.14286
A123: PIÑÓN | B123: 17 CG CROMADO (SIN BORDE) | E123: 0.9 | G123: =((Fórmulas!C$7/Fórmulas!D$7)/Fórmulas!E$7)*E123 -> 2.5714286 | H123: =G123*Fórmulas!B$9 -> 900 | I123: =E123/Fórmulas!E$7 -> 1.5 | J123: =G123*Fórmulas!B$10 -> 1542.8571 | K123: 1 | L123: =((Fórmulas!C$6/Fórmulas!D$6)/0.7)*K123 -> 2.4489796 | M123: =L123*Fórmulas!D$6 -> 857.14286
A124: PIÑÓN | B124: 14 HORSE NEGRO | E124: 1.2 | G124: =((Fórmulas!C$7/Fórmulas!D$7)/Fórmulas!E$7)*E124 -> 3.4285714 | H124: =G124*Fórmulas!B$9 -> 1200 | I124: =E124/Fórmulas!E$7 -> 2 | J124: =G124*Fórmulas!B$10 -> 2057.1429 | K124: 1 | L124: =((Fórmulas!C$6/Fórmulas!D$6)/0.7)*K124 -> 2.4489796 | M124: =L124*Fórmulas!D$6 -> 857.14286
A125: PIÑÓN | B125: 15 HORSE NEGRO | E125: 1.2 | G125: =((Fórmulas!C$7/Fórmulas!D$7)/Fórmulas!E$7)*E125 -> 3.4285714 | H125: =G125*Fórmulas!B$9 -> 1200 | I125: =E125/Fórmulas!E$7 -> 2 | J125: =G125*Fórmulas!B$10 -> 2057.1429 | K125: 1 | L125: =((Fórmulas!C$6/Fórmulas!D$6)/0.7)*K125 -> 2.4489796 | M125: =L125*Fórmulas!D$6 -> 857.14286
A126: PIÑÓN | B126: 16 HORSE NEGRO | E126: 1.2 | G126: =((Fórmulas!C$7/Fórmulas!D$7)/Fórmulas!E$7)*E126 -> 3.4285714 | H126: =G126*Fórmulas!B$9 -> 1200 | I126: =E126/Fórmulas!E$7 -> 2 | J126: =G126*Fórmulas!B$10 -> 2057.1429 | K126: 1 | L126: =((Fórmulas!C$6/Fórmulas!D$6)/0.7)*K126 -> 2.4489796 | M126: =L126*Fórmulas!D$6 -> 857.14286
A127: PIÑÓN | B127: 17 HORSE NEGRO | E127: 1.2 | G127: =((Fórmulas!C$7/Fórmulas!D$7)/Fórmulas!E$7)*E127 -> 3.4285714 | H127: =G127*Fórmulas!B$9 -> 1200 | I127: =E127/Fórmulas!E$7 -> 2 | J127: =G127*Fórmulas!B$10 -> 2057.1429 | K127: 1 | L127: =((Fórmulas!C$6/Fórmulas!D$6)/0.7)*K127 -> 2.4489796 | M127: =L127*Fórmulas!D$6 -> 857.14286
A128: PIÑÓN | B128: 14 HORSE CROMADO | E128: 1.2 | G128: =((Fórmulas!C$7/Fórmulas!D$7)/Fórmulas!E$7)*E128 -> 3.4285714 | H128: =G128*Fórmulas!B$9 -> 1200 | I128: =E128/Fórmulas!E$7 -> 2 | J128: =G128*Fórmulas!B$10 -> 2057.1429 | K128: 1 | L128: =((Fórmulas!C$6/Fórmulas!D$6)/0.7)*K128 -> 2.4489796 | M128: =L128*Fórmulas!D$6 -> 857.14286
A129: PIÑÓN | B129: 15 HORSE CROMADO | E129: 1.2 | G129: =((Fórmulas!C$7/Fórmulas!D$7)/Fórmulas!E$7)*E129 -> 3.4285714 | H129: =G129*Fórmulas!B$9 -> 1200 | I129: =E129/Fórmulas!E$7 -> 2 | J129: =G129*Fórmulas!B$10 -> 2057.1429 | K129: 1 | L129: =((Fórmulas!C$6/Fórmulas!D$6)/0.7)*K129 -> 2.4489796 | M129: =L129*Fórmulas!D$6 -> 857.14286
...

Sheet BICICLETA
E4: UNIDAD | K4: LOTE
B5: CARACTERISTICAS | E5: COSTO $ | F5: INCREMENTO COSTO | G5: VENTA $ | H5: VENTA BS | I5: VENTA USDT | J5: VENTA BS(USDT) | K5: COSTO $ | L5: VENTA $ | M5: VENTA BS
B6: BAJO COSTO
A7: GUALLA | B7: DE FRENO CON FORRO COLORES VARIOS | E7: 0.9 | G7: =((Fórmulas!C$7/Fórmulas!D$7)/Fórmulas!E$7)*E7 -> 2.5714286 | H7: =G7*Fórmulas!B$9 -> 900 | I7: =E7/Fórmulas!E$7 -> 1.5 | J7: =G7*Fórmulas!B$10 -> 1542.8571 | K7: 1 | L7: =((Fórmulas!C$6/Fórmulas!D$6)/0.7)*K7 -> 2.4489796 | M7: =L7*Fórmulas!D$6 -> 857.14286
A8: GUALLA | B8: DE FRENO SIN FORRO | E8: 0.3 | G8: =((Fórmulas!C$7/Fórmulas!D$7)/Fórmulas!E$7)*E8 -> 0.85714286 | H8: =G8*Fórmulas!B$9 -> 300 | I8: =E8/Fórmulas!E$7 -> 0.5 | J8: =G8*Fórmulas!B$10 -> 514.28571 | K8: 1 | L8: =((Fórmulas!C$6/Fórmulas!D$6)/0.7)*K8 -> 2.4489796 | M8: =L8*Fórmulas!D$6 -> 857.14286
A9: GUALLA | B9: DE CAMBIO SIN FORRO | E9: 0.3 | G9: =((Fórmulas!C$7/Fórmulas!D$7)/Fórmulas!E$7)*E9 -> 0.85714286 | H9: =G9*Fórmulas!B$9 -> 300 | I9: =E9/Fórmulas!E$7 -> 0.5 | J9: =G9*Fórmulas!B$10 -> 514.28571 | K9: 1 | L9: =((Fórmulas!C$6/Fórmulas!D$6)/0.7)*K9 -> 2.4489796 | M9: =L9*Fórmulas!D$6 -> 857.14286
G10: =((Fórmulas!C$7/Fórmulas!D$7)/Fórmulas!E$7)*E10 -> 0 | H10: =G10*Fórmulas!B$9 -> 0 | I10: =E10/Fórmulas!E$7 -> 0 | J10: =G10*Fórmulas!B$10 -> 0 | K10: 1 | L10: =((Fórmulas!C$6/Fórmulas!D$6)/0.7)*K10 -> 2.4489796 | M10: =L10*Fórmulas!D$6 -> 857.14286
G11: =((Fórmulas!C$7/Fórmulas!D$7)/Fórmulas!E$7)*E11 -> 0 | H11: =G11*Fórmulas!B$9 -> 0 | I11: =E11/Fórmulas!E$7 -> 0 | J11: =G11*Fórmulas!B$10 -> 0 | K11: 1 | L11: =((Fórmulas!C$6/Fórmulas!D$6)/0.7)*K11 -> 2.4489796 | M11: =L11*Fórmulas!D$6 -> 857.14286
G12: =((Fórmulas!C$7/Fórmulas!D$7)/Fórmulas!E$7)*E12 -> 0 | H12: =G12*Fórmulas!B$9 -> 0 | I12: =E12/Fórmulas!E$7 -> 0 | J12: =G12*Fórmulas!B$10 -> 0 | K12: 1 | L12: =((Fórmulas!C$6/Fórmulas!D$6)/0.7)*K12 -> 2.4489796 | M12: =L12*Fórmulas!D$6 -> 857.14286
G13: =((Fórmulas!C$7/Fórmulas!D$7)/Fórmulas!E$7)*E13 -> 0 | H13: =G13*Fórmulas!B$9 -> 0 | I13: =E13/Fórmulas!E$7 -> 0 | J13: =G13*Fórmulas!B$10 -> 0 | K13: 1 | L13: =((Fórmulas!C$6/Fórmulas!D$6)/0.7)*K13 -> 2.4489796 | M13: =L13*Fórmulas!D$6 -> 857.14286
G14: =((Fórmulas!C$7/Fórmulas!D$7)/Fórmulas!E$7)*E14 -> 0 | H14: =G14*Fórmulas!B$9 -> 0 | I14: =E14/Fórmulas!E$7 -> 0 | J14: =G14*Fórmulas!B$10 -> 0 | K14: 1 | L14: =((Fórmulas!C$6/Fórmulas!D$6)/0.7)*K14 -> 2.4489796 | M14: =L14*Fórmulas!D$6 -> 857.14286
G15: =((Fórmulas!C$7/Fórmulas!D$7)/Fórmulas!E$7)*E15 -> 0 | H15: =G15*Fórmulas!B$9 -> 0 | I15: =E15/Fórmulas!E$7 -> 0 | J15: =G15*Fórmulas!B$10 -> 0 | K15: 1 | L15: =((Fórmulas!C$6/Fórmulas!D$6)/0.7)*K15 -> 2.4489796 | M15: =L15*Fórmulas!D$6 -> 857.14286
G16: =((Fórmulas!C$7/Fórmulas!D$7)/Fórmulas!E$7)*E16 -> 0 | H16: =G16*Fórmulas!B$9 -> 0 | I16: =E16/Fórmulas!E$7 -> 0 | J16: =G16*Fórmulas!B$10 -> 0 | K16: 1 | L16: =((Fórmulas!C$6/Fórmulas!D$6)/0.7)*K16 -> 2.4489796 | M16: =L16*Fórmulas!D$6 -> 857.14286
G17: =((Fórmulas!C$7/Fórmulas!D$7)/Fórmulas!E$7)*E17 -> 0 | H17: =G17*Fórmulas!B$9 -> 0 | I17: =E17/Fórmulas!E$7 -> 0 | J17: =G17*Fórmulas!B$10 -> 0 | K17: 1 | L17: =((Fórmulas!C$6/Fórmulas!D$6)/0.7)*K17 -> 2.4489796 | M17: =L17*Fórmulas!D$6 -> 857.14286
G18: =((Fórmulas!C$7/Fórmulas!D$7)/Fórmulas!E$7)*E18 -> 0 | H18: =G18*Fórmulas!B$9 -> 0 | I18: =E18/Fórmulas!E$7 -> 0 | J18: =G18*Fórmulas!B$10 -> 0 | K18: 1 | L18: =((Fórmulas!C$6/Fórmulas!D$6)/0.7)*K18 -> 2.4489796 | M18: =L18*Fórmulas!D$6 -> 857.14286
G19: =((Fórmulas!C$7/Fórmulas!D$7)/Fórmulas!E$7)*E19 -> 0 | H19: =G19*Fórmulas!B$9 -> 0 | I19: =E19/Fórmulas!E$7 -> 0 | J19: =G19*Fórmulas!B$10 -> 0 | K19: 1 | L19: =((Fórmulas!C$6/Fórmulas!D$6)/0.7)*K19 -> 2.4489796 | M19: =L19*Fórmulas!D$6 -> 857.14286
G20: =((Fórmulas!C$7/Fórmulas!D$7)/Fórmulas!E$7)*E20 -> 0 | H20: =G20*Fórmulas!B$9 -> 0 | I20: =E20/Fórmulas!E$7 -> 0 | J20: =G20*Fórmulas!B$10 -> 0 | K20: 1 | L20: =((Fórmulas!C$6/Fórmulas!D$6)/0.7)*K20 -> 2.4489796 | M20: =L20*Fórmulas!D$6 -> 857.14286
G21: =((Fórmulas!C$7/Fórmulas!D$7)/Fórmulas!E$7)*E21 -> 0 | H21: =G21*Fórmulas!B$9 -> 0 | I21: =E21/Fórmulas!E$7 -> 0 | J21: =G21*Fórmulas!B$10 -> 0 | K21: 1 | L21: =((Fórmulas!C$6/Fórmulas!D$6)/0.7)*K21 -> 2.4489796 | M21: =L21*Fórmulas!D$6 -> 857.14286
... G129: =((Fórmulas!C$7/Fórmulas!D$7)/Fórmulas!E$7)*E129 -> 0 | H129: =G129*Fórmulas!B$9 -> 0 | I129: =E129/Fórmulas!E$7 -> 0 | J129: =G129*Fórmulas!B$10 -> 0 | K129: 1 | L129: =((Fórmulas!C$6/Fórmulas!D$6)/0.7)*K129 -> 2.4489796 | M129: =L129*Fórmulas!D$6 -> 857.14286

Sheet Fórmulas
B5: PRECIO BASE | C5: TASA BINANCE | D5: TASA BCV | F5: COSTO USDT
A6: GENERAL | B6: 49 | C6: 600 | D6: 350 | E6: 0.7 | F6: =((C6/D6)/E6)*B6 -> 120 | G6: =D6*F6 -> 42000
A7: BAJO COSTO | B7: 1 | C7: 600 | D7: 350 | E7: 0.6 | F7: =((C7/D7)/E7)*B7 -> 2.8571429 | G7: =D7*F7 -> 1000
A8: SECUNDARIOS | B8: 10 | C8: 600 | D8: 350 | E8: 0.8 | F8: =((C8/D8)/E8)*B8 -> 21.428571 | G8: =F8*1.7*D8 -> 12750
A9: TASA ACTUAL BCV | B9: 350
A10: TASA ACTUAL USDT | B10: 600
A11: PORCENTAJE EXTRA | B11: 0.1
